Workbook

Sheet Dashboard
C3: Training Desk Dashboard
C8: Refresher Training | E8: First Aid Training | G8: Fire Fighting | I8: Supervisor Training
C11: OEM Training | E11: Service Training
E14: Compliance Dashboard

Sheet Refresher
A1: << Back to Dashboard
A3: Pers No | B3: Name | C3: Designation | D3: Department | E3: Refresher Last Date | F3: Refresher Expiry Date | G3: Due Alert
A4: 10395 | B4: Danguru Saunta | C4: Semiskilled Worker Gr.II | D4: ADMINISTRATION | F4: =IF(ISBLANK(E4), "", EDATE(E4, 60)) | G4: =IF(ISBLANK(F4), "", IF(TODAY()>=EDATE(F4, -1), "Due", "Valid")) -> #VALUE!
A5: 9311 | B5: Satyaban Nayak@Mali | C5: Sr.Semiskilled Worker Gr.II | D5: ADMINISTRATION | E5: 45292 | F5: =IF(ISBLANK(E5), "", EDATE(E5, 60)) -> 47119 | G5: =IF(ISBLANK(F5), "", IF(TODAY()>=EDATE(F5, -1), "Due", "Valid")) -> Valid
A6: 9504 | B6: Mohan Khora | C6: Sr.Semiskilled Worker Gr.II | D6: ADMINISTRATION | E6: 45292 | F6: =IF(ISBLANK(E6), "", EDATE(E6, 60)) -> 47119 | G6: =IF(ISBLANK(F6), "", IF(TODAY()>=EDATE(F6, -1), "Due", "Valid")) -> Valid
A7: 9310 | B7: Chandra Sekhar Lamta | C7: Sr.Semisilled Worker Gr.I | D7: ADMINISTRATION | E7: 45292 | F7: =IF(ISBLANK(E7), "", EDATE(E7, 60)) -> 47119 | G7: =IF(ISBLANK(F7), "", IF(TODAY()>=EDATE(F7, -1), "Due", "Valid")) -> Valid
A8: 9899 | B8: Kamulu Gouda | C8: Technician(Civil) Gr.I | D8: CIVIL | E8: 44562 | F8: =IF(ISBLANK(E8), "", EDATE(E8, 60)) -> 46388 | G8: =IF(ISBLANK(F8), "", IF(TODAY()>=EDATE(F8, -1), "Due", "Valid")) -> Valid
A9: 8137 | B9: Gora Dami | C9: Technician(Electrical) Gr.I | D9: ELECTRICAL | E9: 45658 | F9: =IF(ISBLANK(E9), "", EDATE(E9, 60)) -> 47484 | G9: =IF(ISBLANK(F9), "", IF(TODAY()>=EDATE(F9, -1), "Due", "Valid")) -> Valid
A10: 9905 | B10: Shrabana Kumar Mohanta | C10: Technician(Electrical) Gr.I | D10: ELECTRICAL | E10: 44927 | F10: =IF(ISBLANK(E10), "", EDATE(E10, 60)) -> 46753 | G10: =IF(ISBLANK(F10), "", IF(TODAY()>=EDATE(F10, -1), "Due", "Valid")) -> Valid
A11: 9906 | B11: Laxman Chakie | C11: Technician(Electrical) Gr.I | D11: ELECTRICAL | E11: 44562 | F11: =IF(ISBLANK(E11), "", EDATE(E11, 60)) -> 46388 | G11: =IF(ISBLANK(F11), "", IF(TODAY()>=EDATE(F11, -1), "Due", "Valid")) -> Valid
A12: 7242 | B12: Bhima Mali | C12: Sr.Technician(Instrument) Gr.II | D12: E&I | E12: 44927 | F12: =IF(ISBLANK(E12), "", EDATE(E12, 60)) -> 46753 | G12: =IF(ISBLANK(F12), "", IF(TODAY()>=EDATE(F12, -1), "Due", "Valid")) -> Valid
A13: 9268 | B13: Rasananda Soy | C13: Chargeman Gr.III | D13: ELECTRICAL | E13: 44501 | F13: =IF(ISBLANK(E13), "", EDATE(E13, 60)) -> 46327 | G13: =IF(ISBLANK(F13), "", IF(TODAY()>=EDATE(F13, -1), "Due", "Valid")) -> Valid
A14: 9269 | B14: Rajendra Kumar Maharana | C14: Chargeman Gr.III | D14: ELECTRICAL | E14: 44531 | F14: =IF(ISBLANK(E14), "", EDATE(E14, 60)) -> 46357 | G14: =IF(ISBLANK(F14), "", IF(TODAY()>=EDATE(F14, -1), "Due", "Valid")) -> Valid
A15: 9271 | B15: Kshirasindhu Sahu | C15: Chargeman Gr.III | D15: ELECTRICAL | E15: 45658 | F15: =IF(ISBLANK(E15), "", EDATE(E15, 60)) -> 47484 | G15: =IF(ISBLANK(F15), "", IF(TODAY()>=EDATE(F15, -1), "Due", "Valid")) -> Valid
A16: 9274 | B16: Sk Saukat Alli | C16: Chargeman Gr.III | D16: ELECTRICAL | E16: 44470 | F16: =IF(ISBLANK(E16), "", EDATE(E16, 60)) -> 46296 | G16: =IF(ISBLANK(F16), "", IF(TODAY()>=EDATE(F16, -1), "Due", "Valid")) -> Due
... A25: 7248 | B25: Sanjaya Kumar Sahu | C25: Chargeman Gr.I | D25: E&I | E25: 44562 | F25: =IF(ISBLANK(E25), "", EDATE(E25, 60)) -> 46388 | G25: =IF(ISBLANK(F25), "", IF(TODAY()>=EDATE(F25, -1), "Due", "Valid")) -> Valid
A26: 11047 | B26: Muna Kandhapan | C26: SUPT/SOT | D26: ELECTRICAL | F26: =IF(ISBLANK(E26), "", EDATE(E26, 60)) | G26: =IF(ISBLANK(F26), "", IF(TODAY()>=EDATE(F26, -1), "Due", "Valid")) -> #VALUE!
A27: 11337 | B27: Satya Narayan Sahu | C27: SUPT (JOT)-Electrical | D27: ELECTRICAL | F27: =IF(ISBLANK(E27), "", EDATE(E27, 60)) | G27: =IF(ISBLANK(F27), "", IF(TODAY()>=EDATE(F27, -1), "Due", "Valid")) -> #VALUE!
A28: 11338 | B28: Anuj Kumar | C28: SUPT (JOT)-Electrical | D28: ELECTRICAL | F28: =IF(ISBLANK(E28), "", EDATE(E28, 60)) | G28: =IF(ISBLANK(F28), "", IF(TODAY()>=EDATE(F28, -1), "Due", "Valid")) -> #VALUE!
A29: 11342 | B29: Kishor Chandra Pradhan | C29: SUPT (JOT)-Electrical | D29: ELECTRICAL | F29: =IF(ISBLANK(E29), "", EDATE(E29, 60)) | G29: =IF(ISBLANK(F29), "", IF(TODAY()>=EDATE(F29, -1), "Due", "Valid")) -> #VALUE!
A30: 11344 | B30: Sibaprasad Santra | C30: SUPT (JOT)-Electrical | D30: ELECTRICAL | F30: =IF(ISBLANK(E30), "", EDATE(E30, 60)) | G30: =IF(ISBLANK(F30), "", IF(TODAY()>=EDATE(F30, -1), "Due", "Valid")) -> #VALUE!
A31: 11264 | B31: Chitru Kadia | C31: SUPT(OPTADEF) | D31: ELECTRICAL | F31: =IF(ISBLANK(E31), "", EDATE(E31, 60)) | G31: =IF(ISBLANK(F31), "", IF(TODAY()>=EDATE(F31, -1), "Due", "Valid")) -> #VALUE!
A32: 10132 | B32: Naresh Kumar Bagh | C32: Semiskilled Worker Gr.I | D32: FINANCE & ACCOUNTS | F32: =IF(ISBLANK(E32), "", EDATE(E32, 60)) | G32: =IF(ISBLANK(F32), "", IF(TODAY()>=EDATE(F32, -1), "Due", "Valid")) -> #VALUE!
A33: 10584 | B33: Madhab Nayak | C33: Technician (Mechanical) Gr. III | D33: GEOLOGY | F33: =IF(ISBLANK(E33), "", EDATE(E33, 60)) | G33: =IF(ISBLANK(F33), "", IF(TODAY()>=EDATE(F33, -1), "Due", "Valid")) -> #VALUE!
A34: 9910 | B34: Swagatika Behera | C34: Geological Assistant Gr.II | D34: GEOLOGY | F34: =IF(ISBLANK(E34), "", EDATE(E34, 60)) | G34: =IF(ISBLANK(F34), "", IF(TODAY()>=EDATE(F34, -1), "Due", "Valid")) -> #VALUE!
A35: 10027 | B35: Gagan Chhati | C35: Operator(HEMM) Gr.II | D35: GEOLOGY | E35: 44927 | F35: =IF(ISBLANK(E35), "", EDATE(E35, 60)) -> 46753 | G35: =IF(ISBLANK(F35), "", IF(TODAY()>=EDATE(F35, -1), "Due", "Valid")) -> Valid
A36: 8874 | B36: Mohan Muduli | C36: Operator (HEMM) Gr.I | D36: GEOLOGY | E36: 44927 | F36: =IF(ISBLANK(E36), "", EDATE(E36, 60)) -> 46753 | G36: =IF(ISBLANK(F36), "", IF(TODAY()>=EDATE(F36, -1), "Due", "Valid")) -> Valid
A37: 9909 | B37: Arijit Bera | C37: Geological Assistant Gr.I | D37: GEOLOGY | F37: =IF(ISBLANK(E37), "", EDATE(E37, 60)) | G37: =IF(ISBLANK(F37), "", IF(TODAY()>=EDATE(F37, -1), "Due", "Valid")) -> #VALUE!
A38: 8728 | B38: Girija Prasad Parida | C38: Asst.Geologist | D38: GEOLOGY | F38: =IF(ISBLANK(E38), "", EDATE(E38, 60)) | G38: =IF(ISBLANK(F38), "", IF(TODAY()>=EDATE(F38, -1), "Due", "Valid")) -> #VALUE!
A39: 8542 | B39: Asiskumar Patnaik | C39: Geologist | D39: GEOLOGY | F39: =IF(ISBLANK(E39), "", EDATE(E39, 60)) | G39: =IF(ISBLANK(F39), "", IF(TODAY()>=EDATE(F39, -1), "Due", "Valid")) -> #VALUE!
A40: 10119 | B40: Rabi Mania | C40: Semiskilled Worker Gr.II | D40: GEOLOGY | E40: 45292 | F40: =IF(ISBLANK(E40), "", EDATE(E40, 60)) -> 47119 | G40: =IF(ISBLANK(F40), "", IF(TODAY()>=EDATE(F40, -1), "Due", "Valid")) -> Valid
A41: 11335 | B41: Sunny Abhishek Tigga | C41: SUPT(JOT)-Geologist | D41: GEOLOGY | F41: =IF(ISBLANK(E41), "", EDATE(E41, 60)) | G41: =IF(ISBLANK(F41), "", IF(TODAY()>=EDATE(F41, -1), "Due", "Valid")) -> #VALUE!
A42: 11343 | B42: Ashish Kumar Sethy | C42: SUPT(JOT)-Geologist | D42: GEOLOGY | F42: =IF(ISBLANK(E42), "", EDATE(E42, 60)) | G42: =IF(ISBLANK(F42), "", IF(TODAY()>=EDATE(F42, -1), "Due", "Valid")) -> #VALUE!
A43: 11481 | B43: Jajnadatta Pradhan | C43: SUPT(JOT)-Geologist | D43: GEOLOGY | F43: =IF(ISBLANK(E43), "", EDATE(E43, 60)) | G43: =IF(ISBLANK(F43), "", IF(TODAY()>=EDATE(F43, -1), "Due", "Valid")) -> #VALUE!
A44: 11525 | B44: Shivangee Singha | C44: SUPT(JOT)-Geologist | D44: GEOLOGY | F44: =IF(ISBLANK(E44), "", EDATE(E44, 60)) | G44: =IF(ISBLANK(F44), "", IF(TODAY()>=EDATE(F44, -1), "Due", "Valid")) -> #VALUE!
A45: 7612 | B45: Somanath Acharya | C45: Chargeman Gr.III | D45: ADMINISTRATION | E45: 44409 | F45: =IF(ISBLANK(E45), "", EDATE(E45, 60)) -> 46235 | G45: =IF(ISBLANK(F45), "", IF(TODAY()>=EDATE(F45, -1), "Due", "Valid")) -> Due
A46: 7133 | B46: Rabindranath Tirkey | C46: Chargeman Gr.I | D46: ADMINISTRATION | E46: 44562 | F46: =IF(ISBLANK(E46), "", EDATE(E46, 60)) -> 46388 | G46: =IF(ISBLANK(F46), "", IF(TODAY()>=EDATE(F46, -1), "Due", "Valid")) -> Valid
A47: 10129 | B47: Bhagirathi Pattnaik | C47: Technician(Mechanical) Gr.II | D47: ADMINISTRATION | F47: =IF(ISBLANK(E47), "", EDATE(E47, 60)) | G47: =IF(ISBLANK(F47), "", IF(TODAY()>=EDATE(F47, -1), "Due", "Valid")) -> #VALUE!
A48: 9988 | B48: Debashis Behera | C48: Semiskilled Worker Gr.II | D48: HR | F48: =IF(ISBLANK(E48), "", EDATE(E48, 60)) | G48: =IF(ISBLANK(F48), "", IF(TODAY()>=EDATE(F48, -1), "Due", "Valid")) -> #VALUE!
A49: 10117 | B49: Deepak Kumar Mohanta | C49: Semiskilled Worker Gr.II | D49: ADMINISTRATION | F49: =IF(ISBLANK(E49), "", EDATE(E49, 60)) | G49: =IF(ISBLANK(F49), "", IF(TODAY()>=EDATE(F49, -1), "Due", "Valid")) -> #VALUE!
...

Sheet First_Aid
A1: << Back to Dashboard
A3: Pers No | B3: Name | C3: Designation | D3: Department | E3: First Aid Last Year | F3: First Aid Type | G3: First Aid Expiry Year | H3: Due Alert
A4: 6374 | B4: Bhabani Sankar Rout | C4: Assistant Manager(Administration) | D4: ADMINISTRATION | E4: 2022 | F4: First aid (S) | G4: =IF(ISBLANK(E4), "", IF(OR(F4="First aid (M)", F4="First aid (L)"), "Lifetime", IF(F4="First aid (V)", E4+5, E4+3))) -> 2025 | H4: =IF(ISBLANK(G4), "", IF(G4="Lifetime", "Valid", IF(YEAR(TODAY())>=G4, "Due", "Valid"))) -> Due
A5: 5716 | B5: Jerom Xess | C5: Deputy Manager(Administration) | D5: ADMINISTRATION | E5: 2022 | F5: First aid (V) | G5: =IF(ISBLANK(E5), "", IF(OR(F5="First aid (M)", F5="First aid (L)"), "Lifetime", IF(F5="First aid (V)", E5+5, E5+3))) -> 2027 | H5: =IF(ISBLANK(G5), "", IF(G5="Lifetime", "Valid", IF(YEAR(TODAY())>=G5, "Due", "Valid"))) -> Valid
A6: 10395 | B6: Danguru Saunta | C6: Semiskilled Worker Gr.II | D6: ADMINISTRATION | E6: 2023 | F6: First aid (S) | G6: =IF(ISBLANK(E6), "", IF(OR(F6="First aid (M)", F6="First aid (L)"), "Lifetime", IF(F6="First aid (V)", E6+5, E6+3))) -> 2026 | H6: =IF(ISBLANK(G6), "", IF(G6="Lifetime", "Valid", IF(YEAR(TODAY())>=G6, "Due", "Valid"))) -> Due
A7: 9311 | B7: Satyaban Nayak@Mali | C7: Sr.Semiskilled Worker Gr.II | D7: ADMINISTRATION | E7: 2018 | F7: First aid (S) | G7: =IF(ISBLANK(E7), "", IF(OR(F7="First aid (M)", F7="First aid (L)"), "Lifetime", IF(F7="First aid (V)", E7+5, E7+3))) -> 2021 | H7: =IF(ISBLANK(G7), "", IF(G7="Lifetime", "Valid", IF(YEAR(TODAY())>=G7, "Due", "Valid"))) -> Due
A8: 9504 | B8: Mohan Khora | C8: Sr.Semiskilled Worker Gr.II | D8: ADMINISTRATION | E8: 2023 | F8: First aid (S) | G8: =IF(ISBLANK(E8), "", IF(OR(F8="First aid (M)", F8="First aid (L)"), "Lifetime", IF(F8="First aid (V)", E8+5, E8+3))) -> 2026 | H8: =IF(ISBLANK(G8), "", IF(G8="Lifetime", "Valid", IF(YEAR(TODAY())>=G8, "Due", "Valid"))) -> Due
A9: 9310 | B9: Chandra Sekhar Lamta | C9: Sr.Semisilled Worker Gr.I | D9: ADMINISTRATION | E9: 2019 | F9: First aid (S) | G9: =IF(ISBLANK(E9), "", IF(OR(F9="First aid (M)", F9="First aid (L)"), "Lifetime", IF(F9="First aid (V)", E9+5, E9+3))) -> 2022 | H9: =IF(ISBLANK(G9), "", IF(G9="Lifetime", "Valid", IF(YEAR(TODAY())>=G9, "Due", "Valid"))) -> Due
A10: 10863 | B10: Sanjaya Senapati | C10: AM (Mechanical) | D10: HR | G10: =IF(ISBLANK(E10), "", IF(OR(F10="First aid (M)", F10="First aid (L)"), "Lifetime", IF(F10="First aid (V)", E10+5, E10+3))) | H10: =IF(ISBLANK(G10), "", IF(G10="Lifetime", "Valid", IF(YEAR(TODAY())>=G10, "Due", "Valid"))) -> Valid
A11: 6682 | B11: Chaitanya Murmu | C11: Dy. Manager(Secretarial) | D11: SECRETARIATE | E11: 2021 | F11: First aid (S) | G11: =IF(ISBLANK(E11), "", IF(OR(F11="First aid (M)", F11="First aid (L)"), "Lifetime", IF(F11="First aid (V)", E11+5, E11+3))) -> 2024 | H11: =IF(ISBLANK(G11), "", IF(G11="Lifetime", "Valid", IF(YEAR(TODAY())>=G11, "Due", "Valid"))) -> Due
A12: 5510 | B12: N Srinivasa Sudhakar | C12: Chief General Manager (O&M),Mines | D12: SECRETARIATE | E12: 2024 | F12: First aid (S) | G12: =IF(ISBLANK(E12), "", IF(OR(F12="First aid (M)", F12="First aid (L)"), "Lifetime", IF(F12="First aid (V)", E12+5, E12+3))) -> 2027 | H12: =IF(ISBLANK(G12), "", IF(G12="Lifetime", "Valid", IF(YEAR(TODAY())>=G12, "Due", "Valid"))) -> Valid
A13: 9732 | B13: Purusottam Mohanta | C13: Chief General Manager(Mines) | D13: SECRETARIATE | G13: =IF(ISBLANK(E13), "", IF(OR(F13="First aid (M)", F13="First aid (L)"), "Lifetime", IF(F13="First aid (V)", E13+5, E13+3))) | H13: =IF(ISBLANK(G13), "", IF(G13="Lifetime", "Valid", IF(YEAR(TODAY())>=G13, "Due", "Valid"))) -> Valid
A14: 6133 | B14: Niranjan Ray | C14: Senior Manager(Civil) | D14: CIVIL | G14: =IF(ISBLANK(E14), "", IF(OR(F14="First aid (M)", F14="First aid (L)"), "Lifetime", IF(F14="First aid (V)", E14+5, E14+3))) | H14: =IF(ISBLANK(G14), "", IF(G14="Lifetime", "Valid", IF(YEAR(TODAY())>=G14, "Due", "Valid"))) -> Valid
A15: 9091 | B15: Shailesh Toppo | C15: Senior Manager(Civil) | D15: CIVIL | E15: 2026 | F15: First aid (S) | G15: =IF(ISBLANK(E15), "", IF(OR(F15="First aid (M)", F15="First aid (L)"), "Lifetime", IF(F15="First aid (V)", E15+5, E15+3))) -> 2029 | H15: =IF(ISBLANK(G15), "", IF(G15="Lifetime", "Valid", IF(YEAR(TODAY())>=G15, "Due", "Valid"))) -> Valid
A16: 7559 | B16: Arjun Basu | C16: Deputy General Manager (Civil) | D16: CIVIL | G16: =IF(ISBLANK(E16), "", IF(OR(F16="First aid (M)", F16="First aid (L)"), "Lifetime", IF(F16="First aid (V)", E16+5, E16+3))) | H16: =IF(ISBLANK(G16), "", IF(G16="Lifetime", "Valid", IF(YEAR(TODAY())>=G16, "Due", "Valid"))) -> Valid
A17: 9899 | B17: Kamulu Gouda | C17: Technician(Civil) Gr.I | D17: CIVIL | E17: 2018 | F17: First aid (S) | G17: =IF(ISBLANK(E17), "", IF(OR(F17="First aid (M)", F17="First aid (L)"), "Lifetime", IF(F17="First aid (V)", E17+5, E17+3))) -> 2021 | H17: =IF(ISBLANK(G17), "", IF(G17="Lifetime", "Valid", IF(YEAR(TODAY())>=G17, "Due", "Valid"))) -> Due
A18: 10501 | B18: Vishnu Chandora | C18: Assistant Manager (Instrumentation) | D18: ELECTRICAL | E18: 2024 | F18: First aid (S) | G18: =IF(ISBLANK(E18), "", IF(OR(F18="First aid (M)", F18="First aid (L)"), "Lifetime", IF(F18="First aid (V)", E18+5, E18+3))) -> 2027 | H18: =IF(ISBLANK(G18), "", IF(G18="Lifetime", "Valid", IF(YEAR(TODAY())>=G18, "Due", "Valid"))) -> Valid
A19: 10651 | B19: Sonu Kumar Gupta | C19: Assistant Manager (Electrical) | D19: ELECTRICAL | G19: =IF(ISBLANK(E19), "", IF(OR(F19="First aid (M)", F19="First aid (L)"), "Lifetime", IF(F19="First aid (V)", E19+5, E19+3))) | H19: =IF(ISBLANK(G19), "", IF(G19="Lifetime", "Valid", IF(YEAR(TODAY())>=G19, "Due", "Valid"))) -> Valid
A20: 6709 | B20: Kandra Hembram | C20: Deputy Manager(Electrical) | D20: ELECTRICAL | E20: 2018 | F20: First aid (S) | G20: =IF(ISBLANK(E20), "", IF(OR(F20="First aid (M)", F20="First aid (L)"), "Lifetime", IF(F20="First aid (V)", E20+5, E20+3))) -> 2021 | H20: =IF(ISBLANK(G20), "", IF(G20="Lifetime", "Valid", IF(YEAR(TODAY())>=G20, "Due", "Valid"))) -> Due
A21: 10383 | B21: Prathamesh Ganesh Kokate | C21: Deputy Manager(Electrical) | D21: ELECTRICAL | G21: =IF(ISBLANK(E21), "", IF(OR(F21="First aid (M)", F21="First aid (L)"), "Lifetime", IF(F21="First aid (V)", E21+5, E21+3))) | H21: =IF(ISBLANK(G21), "", IF(G21="Lifetime", "Valid", IF(YEAR(TODAY())>=G21, "Due", "Valid"))) -> Valid
A22: 9748 | B22: Anoj Kumar Swain | C22: Manager(Electrical) | D22: ELECTRICAL | G22: =IF(ISBLANK(E22), "", IF(OR(F22="First aid (M)", F22="First aid (L)"), "Lifetime", IF(F22="First aid (V)", E22+5, E22+3))) | H22: =IF(ISBLANK(G22), "", IF(G22="Lifetime", "Valid", IF(YEAR(TODAY())>=G22, "Due", "Valid"))) -> Valid
A23: 9858 | B23: Rahul Kumar Meena | C23: Manager(Electrical) | D23: ELECTRICAL | E23: 2026 | F23: First aid (S) | G23: =IF(ISBLANK(E23), "", IF(OR(F23="First aid (M)", F23="First aid (L)"), "Lifetime", IF(F23="First aid (V)", E23+5, E23+3))) -> 2029 | H23: =IF(ISBLANK(G23), "", IF(G23="Lifetime", "Valid", IF(YEAR(TODAY())>=G23, "Due", "Valid"))) -> Valid
A24: 9859 | B24: Satya Sunder Behera | C24: Manager(Electrical) | D24: ELECTRICAL | G24: =IF(ISBLANK(E24), "", IF(OR(F24="First aid (M)", F24="First aid (L)"), "Lifetime", IF(F24="First aid (V)", E24+5, E24+3))) | H24: =IF(ISBLANK(G24), "", IF(G24="Lifetime", "Valid", IF(YEAR(TODAY())>=G24, "Due", "Valid"))) -> Valid
A25: 9882 | B25: Samir Kumar Shekhar Deo | C25: Manager (Electrical) | D25: ELECTRICAL | G25: =IF(ISBLANK(E25), "", IF(OR(F25="First aid (M)", F25="First aid (L)"), "Lifetime", IF(F25="First aid (V)", E25+5, E25+3))) | H25: =IF(ISBLANK(G25), "", IF(G25="Lifetime", "Valid", IF(YEAR(TODAY())>=G25, "Due", "Valid"))) -> Valid
A26: 10069 | B26: Naveen Pentela | C26: Manager (Electrical) | D26: MECHANICAL | E26: 2019 | F26: First aid (S) | G26: =IF(ISBLANK(E26), "", IF(OR(F26="First aid (M)", F26="First aid (L)"), "Lifetime", IF(F26="First aid (V)", E26+5, E26+3))) -> 2022 | H26: =IF(ISBLANK(G26), "", IF(G26="Lifetime", "Valid", IF(YEAR(TODAY())>=G26, "Due", "Valid"))) -> Due
A27: 6458 | B27: Sarada Prasad Panda | C27: Senior Manager(Electrical) | D27: ELECTRICAL | G27: =IF(ISBLANK(E27), "", IF(OR(F27="First aid (M)", F27="First aid (L)"), "Lifetime", IF(F27="First aid (V)", E27+5, E27+3))) | H27: =IF(ISBLANK(G27), "", IF(G27="Lifetime", "Valid", IF(YEAR(TODAY())>=G27, "Due", "Valid"))) -> Valid
A28: 9070 | B28: Kaustuv Pattnaik | C28: Sr. Manager (Electrical) | D28: ELECTRICAL | E28: 2024 | F28: First aid (S) | G28: =IF(ISBLANK(E28), "", IF(OR(F28="First aid (M)", F28="First aid (L)"), "Lifetime", IF(F28="First aid (V)", E28+5, E28+3))) -> 2027 | H28: =IF(ISBLANK(G28), "", IF(G28="Lifetime", "Valid", IF(YEAR(TODAY())>=G28, "Due", "Valid"))) -> Valid
A29: 9619 | B29: Dakaneni Veera V S Aditya | C29: Senior Manager (Electrical) | D29: ELECTRICAL | E29: 2021 | F29: First aid (S) | G29: =IF(ISBLANK(E29), "", IF(OR(F29="First aid (M)", F29="First aid (L)"), "Lifetime", IF(F29="First aid (V)", E29+5, E29+3))) -> 2024 | H29: =IF(ISBLANK(G29), "", IF(G29="Lifetime", "Valid", IF(YEAR(TODAY())>=G29, "Due", "Valid"))) -> Due
A30: 9621 | B30: Sunil Kumar Patra | C30: Sr. Manager (Electrical) | D30: ELECTRICAL | E30: 2021 | F30: First aid (S) | G30: =IF(ISBLANK(E30), "", IF(OR(F30="First aid (M)", F30="First aid (L)"), "Lifetime", IF(F30="First aid (V)", E30+5, E30+3))) -> 2024 | H30: =IF(ISBLANK(G30), "", IF(G30="Lifetime", "Valid", IF(YEAR(TODAY())>=G30, "Due", "Valid"))) -> Due
A31: 9668 | B31: Nachiketa Swain | C31: Senior Manager (Electrical) | D31: ELECTRICAL | E31: 2022 | F31: First aid (S) | G31: =IF(ISBLANK(E31), "", IF(OR(F31="First aid (M)", F31="First aid (L)"), "Lifetime", IF(F31="First aid (V)", E31+5, E31+3))) -> 2025 | H31: =IF(ISBLANK(G31), "", IF(G31="Lifetime", "Valid", IF(YEAR(TODAY())>=G31, "Due", "Valid"))) -> Due
A32: 8637 | B32: Dillip Moharana | C32: Deputy General Manager (Electrical) | D32: ELECTRICAL | E32: 2022 | F32: First aid (S) | G32: =IF(ISBLANK(E32), "", IF(OR(F32="First aid (M)", F32="First aid (L)"), "Lifetime", IF(F32="First aid (V)", E32+5, E32+3))) -> 2025 | H32: =IF(ISBLANK(G32), "", IF(G32="Lifetime", "Valid", IF(YEAR(TODAY())>=G32, "Due", "Valid"))) -> Due
A33: 7504 | B33: Harish Kumar Bhagwani | C33: General Manager(Electrical) | D33: ELECTRICAL | G33: =IF(ISBLANK(E33), "", IF(OR(F33="First aid (M)", F33="First aid (L)"), "Lifetime", IF(F33="First aid (V)", E33+5, E33+3))) | H33: =IF(ISBLANK(G33), "", IF(G33="Lifetime", "Valid", IF(YEAR(TODAY())>=G33, "Due", "Valid"))) -> Valid
A34: 11507 | B34: Shaik Zalaluddin Mohammed Akbar | C34: GET(Electrical) | D34: ELECTRICAL | G34: =IF(ISBLANK(E34), "", IF(OR(F34="First aid (M)", F34="First aid (L)"), "Lifetime", IF(F34="First aid (V)", E34+5, E34+3))) | H34: =IF(ISBLANK(G34), "", IF(G34="Lifetime", "Valid", IF(YEAR(TODAY())>=G34, "Due", "Valid"))) -> Valid
A35: 7449 | B35: Sasi Bhusan Behera | C35: Sr.Foreman(Electrical) Gr.I | D35: ELECTRICAL | E35: 2024 | F35: First aid (S) | G35: =IF(ISBLANK(E35), "", IF(OR(F35="First aid (M)", F35="First aid (L)"), "Lifetime", IF(F35="First aid (V)", E35+5, E35+3))) -> 2027 | H35: =IF(ISBLANK(G35), "", IF(G35="Lifetime", "Valid", IF(YEAR(TODAY())>=G35, "Due", "Valid"))) -> Valid
A36: 7465 | B36: Kishor Kumar Lenka | C36: Sr.Foreman(Electical) Gr.I | D36: ELECTRICAL | E36: 2021 | F36: First aid (S) | G36: =IF(ISBLANK(E36), "", IF(OR(F36="First aid (M)", F36="First aid (L)"), "Lifetime", IF(F36="First aid (V)", E36+5, E36+3))) -> 2024 | H36: =IF(ISBLANK(G36), "", IF(G36="Lifetime", "Valid", IF(YEAR(TODAY())>=G36, "Due", "Valid"))) -> Due
A37: 7467 | B37: Raghunath Mohanta | C37: Sr.Foreman(Electrical) Gr.I | D37: ELECTRICAL | G37: =IF(ISBLANK(E37), "", IF(OR(F37="First aid (M)", F37="First aid (L)"), "Lifetime", IF(F37="First aid (V)", E37+5, E37+3))) | H37: =IF(ISBLANK(G37), "", IF(G37="Lifetime", "Valid", IF(YEAR(TODAY())>=G37, "Due", "Valid"))) -> Valid
A38: 8137 | B38: Gora Dami | C38: Technician(Electrical) Gr.I | D38: ELECTRICAL | E38: 2022 | F38: First aid (S) | G38: =IF(ISBLANK(E38), "", IF(OR(F38="First aid (M)", F38="First aid (L)"), "Lifetime", IF(F38="First aid (V)", E38+5, E38+3))) -> 2025 | H38: =IF(ISBLANK(G38), "", IF(G38="Lifetime", "Valid", IF(YEAR(TODAY())>=G38, "Due", "Valid"))) -> Due
A39: 9905 | B39: Shrabana Kumar Mohanta | C39: Technician(Electrical) Gr.I | D39: ELECTRICAL | E39: 2019 | F39: First aid (S) | G39: =IF(ISBLANK(E39), "", IF(OR(F39="First aid (M)", F39="First aid (L)"), "Lifetime", IF(F39="First aid (V)", E39+5, E39+3))) -> 2022 | H39: =IF(ISBLANK(G39), "", IF(G39="Lifetime", "Valid", IF(YEAR(TODAY())>=G39, "Due", "Valid"))) -> Due
A40: 9906 | B40: Laxman Chakie | C40: Technician(Electrical) Gr.I | D40: ELECTRICAL | E40: 2019 | F40: First aid (S) | G40: =IF(ISBLANK(E40), "", IF(OR(F40="First aid (M)", F40="First aid (L)"), "Lifetime", IF(F40="First aid (V)", E40+5, E40+3))) -> 2022 | H40: =IF(ISBLANK(G40), "", IF(G40="Lifetime", "Valid", IF(YEAR(TODAY())>=G40, "Due", "Valid"))) -> Due
A41: 7242 | B41: Bhima Mali | C41: Sr.Technician(Instrument) Gr.II | D41: E&I | G41: =IF(ISBLANK(E41), "", IF(OR(F41="First aid (M)", F41="First aid (L)"), "Lifetime", IF(F41="First aid (V)", E41+5, E41+3))) | H41: =IF(ISBLANK(G41), "", IF(G41="Lifetime", "Valid", IF(YEAR(TODAY())>=G41, "Due", "Valid"))) -> Valid
...

Sheet Fire_Fighting
A1: << Back to Dashboard
A3: Pers No | B3: Name | C3: Designation | D3: Department | E3: Fire Fighting Last Date | F3: Fire Fighting Expiry Date | G3: Due Alert
A4: 6374 | B4: Bhabani Sankar Rout | C4: Assistant Manager(Administration) | D4: ADMINISTRATION | F4: =IF(ISBLANK(E4), "", EDATE(E4, 12)) | G4: =IF(ISBLANK(F4), "", IF(TODAY()>=EDATE(F4, -1), "Due", "Valid")) -> #VALUE!
A5: 5716 | B5: Jerom Xess | C5: Deputy Manager(Administration) | D5: ADMINISTRATION | F5: =IF(ISBLANK(E5), "", EDATE(E5, 12)) | G5: =IF(ISBLANK(F5), "", IF(TODAY()>=EDATE(F5, -1), "Due", "Valid")) -> #VALUE!
A6: 10395 | B6: Danguru Saunta | C6: Semiskilled Worker Gr.II | D6: ADMINISTRATION | F6: =IF(ISBLANK(E6), "", EDATE(E6, 12)) | G6: =IF(ISBLANK(F6), "", IF(TODAY()>=EDATE(F6, -1), "Due", "Valid")) -> #VALUE!
A7: 9311 | B7: Satyaban Nayak@Mali | C7: Sr.Semiskilled Worker Gr.II | D7: ADMINISTRATION | F7: =IF(ISBLANK(E7), "", EDATE(E7, 12)) | G7: =IF(ISBLANK(F7), "", IF(TODAY()>=EDATE(F7, -1), "Due", "Valid")) -> #VALUE!
A8: 9504 | B8: Mohan Khora | C8: Sr.Semiskilled Worker Gr.II | D8: ADMINISTRATION | F8: =IF(ISBLANK(E8), "", EDATE(E8, 12)) | G8: =IF(ISBLANK(F8), "", IF(TODAY()>=EDATE(F8, -1), "Due", "Valid")) -> #VALUE!
A9: 9310 | B9: Chandra Sekhar Lamta | C9: Sr.Semisilled Worker Gr.I | D9: ADMINISTRATION | F9: =IF(ISBLANK(E9), "", EDATE(E9, 12)) | G9: =IF(ISBLANK(F9), "", IF(TODAY()>=EDATE(F9, -1), "Due", "Valid")) -> #VALUE!
A10: 10863 | B10: Sanjaya Senapati | C10: AM (Mechanical) | D10: HR | F10: =IF(ISBLANK(E10), "", EDATE(E10, 12)) | G10: =IF(ISBLANK(F10), "", IF(TODAY()>=EDATE(F10, -1), "Due", "Valid")) -> #VALUE!
A11: 6682 | B11: Chaitanya Murmu | C11: Dy. Manager(Secretarial) | D11: SECRETARIATE | F11: =IF(ISBLANK(E11), "", EDATE(E11, 12)) | G11: =IF(ISBLANK(F11), "", IF(TODAY()>=EDATE(F11, -1), "Due", "Valid")) -> #VALUE!
A12: 5510 | B12: N Srinivasa Sudhakar | C12: Chief General Manager (O&M),Mines | D12: SECRETARIATE | F12: =IF(ISBLANK(E12), "", EDATE(E12, 12)) | G12: =IF(ISBLANK(F12), "", IF(TODAY()>=EDATE(F12, -1), "Due", "Valid")) -> #VALUE!
A13: 9732 | B13: Purusottam Mohanta | C13: Chief General Manager(Mines) | D13: SECRETARIATE | F13: =IF(ISBLANK(E13), "", EDATE(E13, 12)) | G13: =IF(ISBLANK(F13), "", IF(TODAY()>=EDATE(F13, -1), "Due", "Valid")) -> #VALUE!
A14: 6133 | B14: Niranjan Ray | C14: Senior Manager(Civil) | D14: CIVIL | F14: =IF(ISBLANK(E14), "", EDATE(E14, 12)) | G14: =IF(ISBLANK(F14), "", IF(TODAY()>=EDATE(F14, -1), "Due", "Valid")) -> #VALUE!
A15: 9091 | B15: Shailesh Toppo | C15: Senior Manager(Civil) | D15: CIVIL | F15: =IF(ISBLANK(E15), "", EDATE(E15, 12)) | G15: =IF(ISBLANK(F15), "", IF(TODAY()>=EDATE(F15, -1), "Due", "Valid")) -> #VALUE!
... A479: 6677 | B479: Ganti Ramesh Kumar | C479: Superintendent (Mining) Gr.II | D479: ADMINISTRATION | F479: =IF(ISBLANK(E479), "", EDATE(E479, 12)) | G479: =IF(ISBLANK(F479), "", IF(TODAY()>=EDATE(F479, -1), "Due", "Valid")) -> #VALUE!

Sheet Supervisor
A1: << Back to Dashboard
A3: Pers No | B3: Name | C3: Designation | D3: Department | E3: Supervisor Last Date | F3: Supervisor Expiry Date | G3: Due Alert
A4: 7449 | B4: Sasi Bhusan Behera | C4: Sr.Foreman(Electrical) Gr.I | D4: ELECTRICAL | F4: =IF(ISBLANK(E4), "", EDATE(E4, 24)) | G4: =IF(ISBLANK(F4), "", IF(TODAY()>=EDATE(F4, -1), "Due", "Valid")) -> #VALUE!
A5: 7465 | B5: Kishor Kumar Lenka | C5: Sr.Foreman(Electical) Gr.I | D5: ELECTRICAL | F5: =IF(ISBLANK(E5), "", EDATE(E5, 24)) | G5: =IF(ISBLANK(F5), "", IF(TODAY()>=EDATE(F5, -1), "Due", "Valid")) -> #VALUE!
A6: 7467 | B6: Raghunath Mohanta | C6: Sr.Foreman(Electrical) Gr.I | D6: ELECTRICAL | F6: =IF(ISBLANK(E6), "", EDATE(E6, 24)) | G6: =IF(ISBLANK(F6), "", IF(TODAY()>=EDATE(F6, -1), "Due", "Valid")) -> #VALUE!
A7: 9713 | B7: Ramaniranjan Nayak | C7: Foreman(Mechanical) | D7: MECHANICAL | F7: =IF(ISBLANK(E7), "", EDATE(E7, 24)) | G7: =IF(ISBLANK(F7), "", IF(TODAY()>=EDATE(F7, -1), "Due", "Valid")) -> #VALUE!
A8: 7978 | B8: Susanta Kumar Singh | C8: Sr. Foreman (Mechancial) Gr.II | D8: MECHANICAL | F8: =IF(ISBLANK(E8), "", EDATE(E8, 24)) | G8: =IF(ISBLANK(F8), "", IF(TODAY()>=EDATE(F8, -1), "Due", "Valid")) -> #VALUE!
A9: 7256 | B9: Santosh Kumar Mishra | C9: Sr. Foreman (Mechancial) Gr.I | D9: MECHANICAL | F9: =IF(ISBLANK(E9), "", EDATE(E9, 24)) | G9: =IF(ISBLANK(F9), "", IF(TODAY()>=EDATE(F9, -1), "Due", "Valid")) -> #VALUE!
A10: 7278 | B10: Susanta Sekhar Padhee | C10: Sr.Foreman(Mech) Gr.I | D10: MECHANICAL | F10: =IF(ISBLANK(E10), "", EDATE(E10, 24)) | G10: =IF(ISBLANK(F10), "", IF(TODAY()>=EDATE(F10, -1), "Due", "Valid")) -> #VALUE!
A11: 7370 | B11: Pravasa Ranjan Sahoo | C11: Sr.Foreman(Mechancial) Gr.I | D11: MECHANICAL | F11: =IF(ISBLANK(E11), "", EDATE(E11, 24)) | G11: =IF(ISBLANK(F11), "", IF(TODAY()>=EDATE(F11, -1), "Due", "Valid")) -> #VALUE!
A12: 8885 | B12: Santosh Kumar Patro | C12: Jr. Engineer (Electronics) Gr.II | D12: MECHANICAL | F12: =IF(ISBLANK(E12), "", EDATE(E12, 24)) | G12: =IF(ISBLANK(F12), "", IF(TODAY()>=EDATE(F12, -1), "Due", "Valid")) -> #VALUE!
A13: 7572 | B13: Anoop R Lal | C13: Sr.Foreman(Mechancial) Gr.I | D13: MECHANICAL | F13: =IF(ISBLANK(E13), "", EDATE(E13, 24)) | G13: =IF(ISBLANK(F13), "", IF(TODAY()>=EDATE(F13, -1), "Due", "Valid")) -> #VALUE!
A14: 7589 | B14: Anand Mohan Prasad | C14: Sr.Foreman(Mechancial) Gr.I | D14: MECHANICAL | F14: =IF(ISBLANK(E14), "", EDATE(E14, 24)) | G14: =IF(ISBLANK(F14), "", IF(TODAY()>=EDATE(F14, -1), "Due", "Valid")) -> #VALUE!
A15: 10095 | B15: Muguli Rajesh | C15: Asst. Foreman(Mechanical) | D15: MECHANICAL | F15: =IF(ISBLANK(E15), "", EDATE(E15, 24)) | G15: =IF(ISBLANK(F15), "", IF(TODAY()>=EDATE(F15, -1), "Due", "Valid")) -> #VALUE!
... A47: 5731 | B47: Basudev Gajendra | C47: Mine Foreman (SG-1) | D47: MINING | F47: =IF(ISBLANK(E47), "", EDATE(E47, 24)) | G47: =IF(ISBLANK(F47), "", IF(TODAY()>=EDATE(F47, -1), "Due", "Valid")) -> #VALUE!

Sheet OEM_Training
A1: << Back to Dashboard
A3: Pers No | B3: Name | C3: Designation | D3: Department | E3: Machine | F3: From Date | G3: To Date | H3: Man-days
A4: 8143 | B4: MD N ANSARI | C4: Chargeman Gr.II | D4: MINING | E4: In House Ripper -Dozer training | F4: 45699 | G4: 45699 | H4: 1
A5: 8150 | B5: H K Sethy | C5: Chargeman Gr.II | D5: MINING | E5: In House Ripper -Dozer training | F5: 45699 | G5: 45699 | H5: 1
A6: 8223 | B6: R MOHANANDIA | C6: Chargeman Gr.II | D6: MINING | E6: In House Ripper -Dozer training | F6: 45699 | G6: 45699 | H6: 1
A7: 9262 | B7: J MUDI | C7: Chargeman Gr.III | D7: MINING | E7: In House Ripper -Dozer training | F7: 45699 | G7: 45699 | H7: 1
A8: 9951 | B8: DHANURJAY NAYAK | C8: Operator(HEMM) Gr.II | D8: MINING | E8: In House Ripper -Dozer training | F8: 45699 | G8: 45699 | H8: 1
A9: 9965 | B9: ARUN PRADHAN | C9: Operator(HEMM) Gr.I | D9: MINING | E9: In House Ripper -Dozer training | F9: 45699 | G9: 45699 | H9: 1
A10: 7243 | B10: SINGURU SAUNTA | C10: Chargeman Gr.III | D10: MINING | E10: In House Ripper -Dozer training | F10: 45700 | G10: 45700 | H10: 1
A11: 7567 | B11: B GOUR | C11: Chargeman Gr.I | D11: MINING | E11: In House Ripper -Dozer training | F11: 45700 | G11: 45700 | H11: 1
A12: 8149 | B12: P K SAHOO | C12: Chargeman Gr.II | D12: MINING | E12: In House Ripper -Dozer training | F12: 45700 | G12: 45700 | H12: 1
A13: 8221 | B13: B K MOHANTA | C13: Chargeman Gr.II | D13: MINING | E13: In House Ripper -Dozer training | F13: 45700 | G13: 45700 | H13: 1
A14: 8734 | B14: S BARIK | C14: Chargeman Gr.II | D14: MINING | E14: In House Ripper -Dozer training | F14: 45700 | G14: 45700 | H14: 1
A15: 9505 | B15: B KULDEEP | C15: Sr.Semiskilled Worker Gr.II | D15: MINING | E15: In House Ripper -Dozer training | F15: 45700 | G15: 45700 | H15: 1
... A30: 8738 | B30: Satchidananda Nath | C30: Chargeman Gr.II | D30: MINING | E30: In House Ripper -Dozer training | F30: 45701 | G30: 45701 | H30: 1
A31: nan
A32: 7360 | B32: B NAYAK | C32: Chargeman Gr.I | D32: MINING | E32: WHEEL LOADER (WA700 & WA800) | F32: 45888 | G32: 45888 | H32: 1
A33: 9246 | B33: K KARNA | C33: Chargeman Gr.III | D33: MINING | E33: WHEEL LOADER (WA700 & WA800) | F33: 45888 | G33: 45888 | H33: 1
A34: 9261 | B34: P PARIDA | C34: Chargeman Gr.III | D34: MINING | E34: WHEEL LOADER (WA700 & WA800) | F34: 45888 | G34: 45888 | H34: 1
A35: 9308 | B35: M R ROUT | C35: Mine Foreman | D35: MINING | E35: WHEEL LOADER (WA700 & WA800) | F35: 45888 | G35: 45888 | H35: 1
A36: 9720 | B36: M K JANI | C36: Operator(HEMM) Gr.I | D36: MINING | E36: WHEEL LOADER (WA700 & WA800) | F36: 45888 | G36: 45888 | H36: 1
A37: 9724 | B37: S BHOWMIK | C37: Sr. Mining Mate Gr.I | D37: MINING | E37: WHEEL LOADER (WA700 & WA800) | F37: 45888 | G37: 45888 | H37: 1
A38: 9819 | B38: PRAFUL KHARA | C38: Operator(HEMM) Gr.I | D38: MINING | E38: WHEEL LOADER (WA700 & WA800) | F38: 45888 | G38: 45888 | H38: 1
A39: 9822 | B39: S S PRADHAN | C39: Operator(HEMM) Gr.I | D39: MINING | E39: WHEEL LOADER (WA700 & WA800) | F39: 45888 | G39: 45888 | H39: 1
A40: 9832 | B40: ABHISEKH DUTTA | C40: Operator(HEMM) Gr.I | D40: MINING | E40: WHEEL LOADER (WA700 & WA800) | F40: 45888 | G40: 45888 | H40: 1
A41: 9836 | B41: DEEPAK SINGH | C41: Operator(HEMM) Gr.I | D41: MINING | E41: WHEEL LOADER (WA700 & WA800) | F41: 45888 | G41: 45888 | H41: 1
A42: 9954 | B42: S K BARIK | C42: Operator(HEMM) Gr.I | D42: MINING | E42: WHEEL LOADER (WA700 & WA800) | F42: 45888 | G42: 45888 | H42: 1
A43: 9965 | B43: Arun Pradhan | C43: Operator(HEMM) Gr.I | D43: MINING | E43: WHEEL LOADER (WA700 & WA800) | F43: 45888 | G43: 45888 | H43: 1
A44: C2615 | B44: A Majhi | E44: WHEEL LOADER (WA700 & WA800) | F44: 45888 | G44: 45888 | H44: 1
A45: C2621 | B45: Murali Lamta | E45: WHEEL LOADER (WA700 & WA800) | F45: 45888 | G45: 45888 | H45: 1
A46: C153 | B46: K C Pradhan | E46: WHEEL LOADER (WA700 & WA800) | F46: 45888 | G46: 45888 | H46: 1
A47: 10374 | B47: Krishna Ch Maharana | C47: Mining Mate Gr.II | D47: MINING | E47: WHEEL LOADER (WA700 & WA800) | F47: 45888 | G47: 45888 | H47: 1
A48: 10385 | B48: Nakul Mali | C48: Operator(HEMM) Gr.III | D48: MINING | E48: WHEEL LOADER (WA700 & WA800) | F48: 45888 | G48: 45888 | H48: 1
A49: 8243 | B49: P L Mohanta | C49: Asst. Manager (Mining) | D49: MINING | E49: WHEEL LOADER (WA700 & WA800) | F49: 45888 | G49: 45888 | H49: 1
A50: 9649 | B50: Dashrath Kumar | C50: Senior Manager (Mines) | D50: MINING | E50: WHEEL LOADER (WA700 & WA800) | F50: 45888 | G50: 45888 | H50: 1
A51: 10674 | B51: Chayan Das | C51: Deputy Manager(Mining) | D51: MINING | E51: WHEEL LOADER (WA700 & WA800) | F51: 45888 | G51: 45888 | H51: 1
A52: 6914 | B52: I P GAMANGO | C52: Superintendent(HEMM) Gr.II | D52: MINING | E52: WHEEL LOADER (WA700 & WA800) | F52: 45889 | G52: 45889 | H52: 1
A53: 7261 | B53: S N PALO | C53: Chargeman Gr.I | D53: MINING | E53: WHEEL LOADER (WA700 & WA800) | F53: 45889 | G53: 45889 | H53: 1
A54: 8734 | B54: S BARIK | C54: Chargeman Gr.II | D54: MINING | E54: WHEEL LOADER (WA700 & WA800) | F54: 45889 | G54: 45889 | H54: 1
A55: 9259 | B55: B K KHARA | C55: Chargeman Gr.III | D55: MINING | E55: WHEEL LOADER (WA700 & WA800) | F55: 45889 | G55: 45889 | H55: 1
...

Sheet Service_Training
A1: << Back to Dashboard
A3: Pers No | B3: Name | C3: Designation | D3: Department | E3: Type of Training | F3: Topic | G3: Location | H3: From Date | I3: To Date | J3: Total Days
A4: 9720 | B4: Manoj kumar Jani | C4: Operator(HEMM) Gr.I | D4: MINING | E4: SERVICE TRAINING | F4: BH100 AND BH60ML | G4: Mysuru | H4: 45157 | I4: 45163 | J4: 7
A5: 9721 | B5: M K Cheety | C5: Operator(HEMM) Gr.I | D5: MINING | E5: SERVICE TRAINING | F5: BH100 AND BH60ML | G5: Mysuru | H5: 45157 | I5: 45163 | J5: 7
A6: 9738 | B6: Jogesh Choudhury | C6: Operator(HEMM) Gr.I | D6: MINING | E6: SERVICE TRAINING | F6: BH100 AND BH60ML | G6: Mysuru | H6: 45157 | I6: 45163 | J6: 7
A7: 9812 | B7: Prashant Khora | C7: Operator(HEMM) Gr.I | D7: MINING | E7: SERVICE TRAINING | F7: BH100 AND BH60ML | G7: Mysuru | H7: 45157 | I7: 45163 | J7: 7
A8: 9814 | B8: ABHIRAM MALI | C8: Operator(HEMM) Gr.I | D8: MINING | E8: SERVICE TRAINING | F8: BH100 AND BH60ML | G8: Mysuru | H8: 45157 | I8: 45163 | J8: 7
A9: 9816 | B9: Ashok kumar Nayak | C9: Operator(HEMM) Gr.I | D9: MINING | E9: SERVICE TRAINING | F9: BH100 AND BH60ML | G9: Mysuru | H9: 45157 | I9: 45163 | J9: 7
A10: 9817 | B10: Jhuna Turuk | C10: Operator(HEMM) Gr.I | D10: MINING | E10: SERVICE TRAINING | F10: BH100 AND BH60ML | G10: Mysuru | H10: 45157 | I10: 45163 | J10: 7
A11: 9819 | B11: Praful Khora | C11: Operator(HEMM) Gr.I | D11: MINING | E11: SERVICE TRAINING | F11: BH100 AND BH60ML | G11: Mysuru | H11: 45157 | I11: 45163 | J11: 7
A12: 9820 | B12: M S nag | C12: Operator(HEMM) Gr.I | D12: MINING | E12: SERVICE TRAINING | F12: BH100 AND BH60ML | G12: Mysuru | H12: 45157 | I12: 45163 | J12: 7
A13: 9505 | B13: Bhajman kuldip | C13: Sr.Semiskilled Worker Gr.II | D13: MINING | E13: SERVICE TRAINING | F13: BH100 AND BH60ML | G13: Mysuru | H13: 45157 | I13: 45163 | J13: 7
A14: 9818 | B14: Brundaban Choudhury | C14: Operator(HEMM) Gr.I | D14: MINING | E14: SERVICE TRAINING | F14: BH100 AND BH60ML | G14: Mysuru | H14: 45157 | I14: 45163 | J14: 7
A15: 9821 | B15: Manu Mali | E15: SERVICE TRAINING | F15: BH100 AND BH60ML | G15: MYSURU | H15: 45493 | I15: 45499 | J15: 7
A16: 9822 | B16: S S Pradhan | C16: Operator(HEMM) Gr.I | D16: MINING | E16: SERVICE TRAINING | F16: BH100 AND BH60ML | G16: MYSURU | H16: 45493 | I16: 45499 | J16: 7
A17: 7243 | B17: Singru Santa | C17: Chargeman Gr.III | D17: MINING | E17: SERVICE TRAINING | F17: BH100 AND BH60ML | G17: MYSURU | H17: 45493 | I17: 45499 | J17: 7
A18: 9825 | B18: S K Hikaka | C18: Operator(HEMM) Gr.I | D18: MINING | E18: SERVICE TRAINING | F18: BH100 AND BH60ML | G18: MYSURU | H18: 45493 | I18: 45499 | J18: 7
A19: 9826 | B19: Laxman Gouda | E19: SERVICE TRAINING | F19: BH100 AND BH60ML | G19: MYSURU | H19: 45493 | I19: 45499 | J19: 7
A20: 9830 | B20: G Badnayak | C20: Operator(HEMM) Gr.I | D20: MINING | E20: SERVICE TRAINING | F20: BH100 AND BH60ML | G20: MYSURU | H20: 45493 | I20: 45499 | J20: 7
A21: 9828 | B21: S K mallick | C21: Operator(HEMM) Gr.I | D21: MINING | E21: SERVICE TRAINING | F21: BH100 AND BH60ML | G21: MYSURU | H21: 45496 | I21: 45502 | J21: 7
A22: 9829 | B22: S R Mohanty | C22: Operator(HEMM) Gr.I | D22: MINING | E22: SERVICE TRAINING | F22: BH100 AND BH60ML | G22: MYSURU | H22: 45496 | I22: 45502 | J22: 7
A23: 9831 | B23: Krushna Muduli | C23: Operator(HEMM) Gr.I | D23: MINING | E23: SERVICE TRAINING | F23: BH100 AND BH60ML | G23: MYSURU | H23: 45496 | I23: 45502 | J23: 7
A24: 9832 | B24: Abhishek Dutta | C24: Operator(HEMM) Gr.I | D24: MINING | E24: SERVICE TRAINING | F24: BH100 AND BH60ML | G24: MYSURU | H24: 45496 | I24: 45502 | J24: 7
A25: 9833 | B25: Dullabh Nag | C25: Operator(HEMM) Gr.I | D25: MINING | E25: SERVICE TRAINING | F25: BH100 AND BH60ML | G25: MYSURU | H25: 45496 | I25: 45502 | J25: 7
A26: 9946 | B26: Gopinath Gouda | C26: Operator(HEMM) Gr.I | D26: MINING | E26: SERVICE TRAINING | F26: BH100 AND BH60ML | G26: MYSURU | H26: 45496 | I26: 45502 | J26: 7
A27: 9728 | B27: Gopal Renasia | C27: Asst. Foreman (Mining) | D27: MINING | E27: WI Training | F27: Orientation Training Course on workmen Inspector | G27: Dhanbad | H27: 45488 | I27: 45500 | J27: 13
A28: 9952 | B28: S K Swain | C28: Operator(HEMM) Gr.I | D28: MINING | E28: SERVICE TRAINING | F28: BH100 AND BH60ML | G28: MYSURU | H28: 45850 | I28: 45856 | J28: 7
A29: 9956 | B29: Suresh kumar Hantal | C29: Operator(HEMM) Gr.I | D29: MINING | E29: SERVICE TRAINING | F29: BH100 AND BH60ML | G29: MYSURU | H29: 45850 | I29: 45856 | J29: 7
A30: 9835 | B30: Amresh Kr Sethy | C30: Operator(HEMM) Gr.I | D30: MINING | E30: SERVICE TRAINING | F30: BH100 AND BH60ML | G30: MYSURU | H30: 45850 | I30: 45856 | J30: 7
A31: 9959 | B31: Mukesh Das | C31: Operator(HEMM) Gr.I | D31: MINING | E31: SERVICE TRAINING | F31: BH100 AND BH60ML | G31: MYSURU | H31: 45850 | I31: 45856 | J31: 7
... A59: 10411 | B59: R K Nayak | C59: Operator (HEMM) Gr.III | D59: MINING | E59: SERVICE TRAINING | F59: Ripper- Dozer Komatsu | G59: Singruli | H59: 46209 | I59: 46215 | J59: 7
A60: 9038 | B60: M R Rout | E60: Supervisor Statutory Training | F60: The OSHWC-2020 | G60: Kolkata | H60: 46214 | I60: 46220 | J60: 7
A61: 9723 | B61: Pintu Jena | C61: Sr. Mining Mate Gr.I | D61: MINING | E61: Supervisor Statutory Training | F61: The OSHWC-2021 | G61: Kolkata | H61: 46214 | I61: 46220 | J61: 7
A62: 10356 | B62: S K Mohanty | C62: Jr.Foreman(Mining) | D62: MINING | E62: Supervisor Statutory Training | F62: The OSHWC-2022 | G62: Kolkata | H62: 46214 | I62: 46220 | J62: 7

Sheet Compliance
A1: << Back to Dashboard
A4: Training Type | B4: Total Eligible | C4: Total Valid | D4: Total Due / Pending | E4: Compliance %
A5: Refresher | B5: =COUNTA(Refresher!A4:A5000) -> 304 | C5: =COUNTIF(Refresher!G4:G5000, "Valid") -> 202 | D5: =B5-C5 -> 102 | E5: =IF(B5=0, 0, C5/B5) -> 0.66447368
A6: First Aid | B6: =COUNTA(First_Aid!A4:A4998) -> 474 | C6: =COUNTIF(First_Aid!H4:H4998, "Valid") -> 321 | D6: =B6-C6 -> 153 | E6: =IF(B6=0, 0, C6/B6) -> 0.67721519
A7: Fire Fighting | B7: =COUNTA(Fire_Fighting!A4:A5000) -> 476 | C7: =COUNTIF(Fire_Fighting!G4:G5000, "Valid") -> 0 | D7: =B7-C7 -> 476 | E7: =IF(B7=0, 0, C7/B7) -> 0
A8: Supervisor | B8: =COUNTA(Supervisor!A4:A5000) -> 44 | C8: =COUNTIF(Supervisor!G4:G5000, "Valid") -> 0 | D8: =B8-C8 -> 44 | E8: =IF(B8=0, 0, C8/B8) -> 0
A11: Refresher Due Year | B11: Employee Count
A12: 2026 | B12: =COUNTIFS(Refresher!F4:F5000, ">=2026-01-01", Refresher!F4:F5000, "<=2026-12-31") -> 71
A13: 2027 | B13: =COUNTIFS(Refresher!F4:F5000, ">=2027-01-01", Refresher!F4:F5000, "<=2027-12-31") -> 54
A14: 2028 | B14: =COUNTIFS(Refresher!F4:F5000, ">=2028-01-01", Refresher!F4:F5000, "<=2028-12-31") -> 43
A15: 2029 | B15: =COUNTIFS(Refresher!F4:F5000, ">=2029-01-01", Refresher!F4:F5000, "<=2029-12-31") -> 39
A16: 2030 | B16: =COUNTIFS(Refresher!F4:F5000, ">=2030-01-01", Refresher!F4:F5000, "<=2030-12-31") -> 31
A17: No Data / Pending | B17: =COUNTIF(Refresher!F4:F5000, "") - (5000 - COUNTA(Refresher!A4:A5000)) -> 63
